Workbook

Sheet Sheet 1
A1: district_name | B1: type_name | C1: area_ha | D1: year
A2: Ahmadabad | B2: Bare areas | C2: 151.4012 | D2: 2017
A3: Ahmadabad | B3: Bare areas | C3: 120.2597 | D3: 2016
A4: Ahmadabad | B4: Bare areas | C4: 186.2974 | D4: 2018
A5: Ahmadabad | B5: Bare areas | C5: 149.6811 | D5: 2015
A6: Ahmadabad | B6: Bare areas | C6: 160.6177 | D6: 2020
A7: Ahmadabad | B7: Bare areas | C7: 326.6477 | D7: 2022
A8: Ahmadabad | B8: Bare areas | C8: 178.167 | D8: 2019
A9: Ahmadabad | B9: Bare areas | C9: 205.6365 | D9: 2021
A10: Ahmadabad | B10: Closed deciduous broadleaved forest | C10: 6716.457 | D10: 2019
A11: Ahmadabad | B11: Closed deciduous broadleaved forest | C11: 4734.792 | D11: 2020
A12: Ahmadabad | B12: Closed deciduous broadleaved forest | C12: 6633.458 | D12: 2018
A13: Ahmadabad | B13: Closed deciduous broadleaved forest | C13: 7347.824 | D13: 2015
... A4275: Valsad | B4275: Water body | C4275: 2698.059 | D4275: 2020

Sheet Old Satellite Data
A1: c | C1: year
A2: district_name | B2: type_name | C2: 2015 | D2: 2016 | E2: 2017 | F2: 2018 | G2: 2019 | H2: 2020 | I2: 2021 | J2: 2022 | K2: Grand Total
A3: Ahmadabad | B3: Bare areas | C3: 149.6811 | D3: 120.2597 | E3: 151.4012 | F3: 186.2974 | G3: 178.167 | H3: 160.6177 | I3: 205.6365 | J3: 326.6477 | K3: 1478.7083
B4: Closed deciduous broadleaved forest | C4: 7347.824 | D4: 6983.03 | E4: 6564.012 | F4: 6633.458 | G4: 6716.457 | H4: 4734.792 | I4: 3986.956 | J4: 4100.883 | K4: 47067.412
B5: Closed evergreen broadleaved forest | C5: 0.923507 | D5: 0.923507 | K5: 1.847014
B6: Closed evergreen needle-leaved forest | C6: 4.590198 | G6: 2.75303 | I6: 5.505937 | J6: 2.753359 | K6: 15.602524
B7: Consolidated bare areas | C7: 0.917022 | F7: 4.572985 | G7: 3.674177 | H7: 2.75235 | I7: 8.253731 | J7: 3.672839 | K7: 23.843104
B8: Deciduous shrubland | C8: 448.1351 | D8: 615.2162 | E8: 444.4746 | F8: 319.5869 | G8: 351.6785 | H8: 351.6043 | I8: 335.0885 | J8: 433.4529 | K8: 3299.237
B9: Flooded flat | C9: 6220.503 | D9: 6938.865 | E9: 7171.394 | F9: 8230.258 | G9: 8310.349 | H9: 8389.824 | I9: 6427.168 | J9: 6079.341 | K9: 57767.702
B10: Grassland | C10: 20884.28 | D10: 20514.22 | E10: 18395.59 | F10: 18865.97 | G10: 19856.44 | H10: 17788.52 | I10: 18645.17 | J10: 18052.8 | K10: 153002.99
B11: Herbaceous cover cropland | C11: 16205.27 | D11: 16442.33 | E11: 17175.16 | F11: 15978 | G11: 16047.98 | H11: 15273.94 | I11: 15043.55 | J11: 15100.75 | K11: 127266.98
B12: Impervious surfaces | C12: 46515.16 | D12: 47142.37 | E12: 48149.71 | F12: 47793.7 | G12: 48312.87 | H12: 48108.91 | I12: 48451.08 | J12: 48503.74 | K12: 382977.54
B13: Irrigated cropland | C13: 189098 | D13: 187490.2 | E13: 187706.8 | F13: 185315.3 | G13: 186363.8 | H13: 198757.6 | I13: 204782.8 | J13: 205713.4 | K13: 1545227.9
B14: Mangrove | E14: 9.214536 | F14: 2.764018 | G14: 0.921352 | I14: 2.763703 | J14: 1.842516 | K14: 17.506125
B15: Marsh | C15: 3562.288 | D15: 3525.226 | E15: 2795.348 | F15: 3110.482 | G15: 3632.993 | H15: 3866.17 | I15: 2719.939 | J15: 3087.903 | K15: 26300.349
B16: Open deciduous broadleaved forest | C16: 58.01703 | D16: 39.59624 | E16: 43.3112 | F16: 38.7009 | G16: 64.5098 | H16: 41.46728 | I16: 44.20073 | J16: 41.4317 | K16: 371.23488
B17: Open deciduous needle-leaved forest | C17: 4.607705 | D17: 2.766876 | E17: 2.760566 | F17: 2.766409 | G17: 10.10841 | H17: 9.182305 | I17: 10.1163 | J17: 15.65649 | K17: 57.965061
B18: Open evergreen broadleaved forest | C18: 160.3212 | D18: 163.0731 | E18: 183.3618 | F18: 103.1949 | G18: 75.50146 | H18: 81.06997 | I18: 126.3015 | J18: 143.824 | K18: 1036.6479
B19: Open evergreen needle-leaved forest | C19: 219.1283 | D19: 199.0717 | E19: 185.352 | F19: 140.1257 | G19: 105.0418 | H19: 141.9648 | I19: 202.7519 | J19: 198.2274 | K19: 1391.6636
B20: Open mixed leaf forest | C20: 276.4018 | D20: 284.7412 | E20: 301.3576 | F20: 176.8543 | G20: 220.1731 | H20: 219.206 | I20: 282.0131 | J20: 278.346 | K20: 2039.0931
B21: Rainfed cropland | C21: 472387.2 | D21: 473477.2 | E21: 475701.5 | F21: 479408.3 | G21: 474642.1 | H21: 465613.3 | I21: 459779.7 | J21: 459838.3 | K21: 3760847.6
B22: Shrubland | C22: 3886.975 | D22: 3183.942 | E22: 2729.314 | F22: 2990.223 | G22: 4281.405 | H22: 5126.907 | I22: 5769.957 | J22: 5373.06 | K22: 33341.783
B23: Sparse vegetation | C23: 2528.606 | D23: 2827.531 | E23: 2749.504 | F23: 2212.924 | G23: 2034.68 | H23: 2039.988 | I23: 1870.924 | J23: 1747.833 | K23: 18011.99
B24: Tidal flat | C24: 1082.701 | D24: 1076.259 | E24: 985.0091 | F24: 1034.783 | G24: 1073.485 | H24: 1087.328 | I24: 1105.783 | J24: 1069.848 | K24: 8515.1961
B25: Unconsolidated bare areas | C25: 20.18413 | D25: 23.84642 | E25: 14.67267 | F25: 41.27944 | G25: 29.34298 | H25: 49.49559 | I25: 43.08691 | J25: 45.84027 | K25: 267.74841
B26: Unknown | C26: 3.678916 | D26: 26.70858 | E26: 66.32674 | F26: 38.71979 | G26: 24.89389 | H26: 12.90193 | I26: 6.455204 | J26: 7.371178 | K26: 187.05623
B27: Water body | C27: 2477.589 | D27: 2465.536 | E27: 2017.364 | F27: 914.7171 | G27: 1203.593 | H27: 1685.415 | I27: 3687.74 | J27: 3376.046 | K27: 17828
A28: Ahmadabad Total | C28: 773542.98 | D28: 773542.91 | E28: 773542.94 | F28: 773542.98 | G28: 773542.92 | H28: 773542.96 | I28: 773542.94 | J28: 773542.97 | K28: 6188343.6
A29: Amreli | B29: Bare areas | C29: 40.92466 | D29: 24.17713 | E29: 31.61388 | F29: 33.4772 | G29: 51.18006 | H29: 28.8531 | I29: 27.91945 | J29: 32.55338 | K29: 270.69886
B30: Closed deciduous broadleaved forest | C30: 45010.18 | D30: 44957.99 | E30: 42051.28 | F30: 39716.8 | G30: 42639.79 | H30: 46207.27 | I30: 47346.95 | J30: 46129.82 | K30: 354060.08
B31: Closed evergreen broadleaved forest | H31: 2.790152 | K31: 2.790152
B32: Closed evergreen needle-leaved forest | J32: 0.930833 | K32: 0.930833
B33: Deciduous shrubland | C33: 404.4137 | D33: 417.4442 | E33: 368.0627 | F33: 337.351 | G33: 312.1814 | H33: 320.5503 | I33: 307.5205 | J33: 336.3855 | K33: 2803.9093
B34: Flooded flat | C34: 3996.502 | D34: 4057.174 | E34: 4047.467 | F34: 3810.046 | G34: 4153.294 | H34: 5062.22 | I34: 5047.84 | J34: 4842.32 | K34: 35016.863
B35: Grassland | C35: 2418.626 | D35: 2305.683 | E35: 2250.76 | F35: 2709.769 | G35: 2588.293 | H35: 2313.33 | I35: 2275.894 | J35: 2282.13 | K35: 19144.485
B36: Herbaceous cover cropland | C36: 3858.591 | D36: 3586.53 | E36: 3613.377 | F36: 3655.021 | G36: 4002.952 | H36: 3462.098 | I36: 3346.157 | J36: 3358.281 | K36: 28883.007
B37: Impervious surfaces | C37: 16313.37 | D37: 16643.44 | E37: 17219.83 | F37: 16483.22 | G37: 15845.5 | H37: 16303.64 | I37: 16644.72 | J37: 16479.36 | K37: 131933.08
B38: Irrigated cropland | C38: 50716.6 | D38: 50266.81 | E38: 48863.26 | F38: 48578.3 | G38: 49686.82 | H38: 49358.66 | I38: 47727.12 | J38: 47490.21 | K38: 392687.78
B39: Mangrove | C39: 81.98316 | D39: 107.1362 | E39: 105.2771 | F39: 84.78077 | G39: 104.3393 | H39: 124.8283 | I39: 103.4039 | J39: 100.6167 | K39: 812.36543
B40: Marsh | C40: 1827.458 | D40: 1633.212 | E40: 1370.186 | F40: 1364.387 | G40: 1626.586 | H40: 1873.392 | I40: 995.8488 | J40: 1047.362 | K40: 11738.432
...

Sheet State_Restructured
A1: Sector | B1: Sub- Sector | C1: Sub- Sector | D1: Sub- Sector | E1: Category | F1: Data Source | G1: Year | H1: Climate Type | I1: Activity Data(ha)(Area of Forest Land) | J1: Annual Change in Carbon Stock(tonnes C yr-1) | K1: Emission (Ton yr^-1)/(Conversion of C to CO2) | L1: GWP20 | M1: GWP100 | N1: CO2e GWP20 | O1: CO2e GWP100
A2: 3 Agriculture, Forestry & Other Land Use | B2: 3B Land | C2: 3B1 Forest Land | D2: 3B1a Forest Land Remaining Forest Land | E2: Annual increase in carbon stocks in biomass | F2: GLC_FCS30D | G2: 2012 | H2: Tropical Dry | I2: 2277376 | J2: 10018631 | K2: -36734980 | L2: 1 | M2: 1 | N2: =K2*L2 -> -36734980 | O2: =K2*M2 -> -36734980
A3: 3 Agriculture, Forestry & Other Land Use | B3: 3B Land | C3: 3B1 Forest Land | D3: 3B1a Forest Land Remaining Forest Land | E3: Annual increase in carbon stocks in biomass | F3: GLC_FCS30D | G3: 2013 | H3: Tropical Dry | I3: 2282452 | J3: 10040962 | K3: -36816861 | L3: 1 | M3: 1 | N3: =K3*L3 -> -36816861 | O3: =K3*M3 -> -36816861
A4: 3 Agriculture, Forestry & Other Land Use | B4: 3B Land | C4: 3B1 Forest Land | D4: 3B1a Forest Land Remaining Forest Land | E4: Annual increase in carbon stocks in biomass | F4: GLC_FCS30D | G4: 2014 | H4: Tropical Dry | I4: 2286598 | J4: 10059203 | K4: -36883743 | L4: 1 | M4: 1 | N4: =K4*L4 -> -36883743 | O4: =K4*M4 -> -36883743
A5: 3 Agriculture, Forestry & Other Land Use | B5: 3B Land | C5: 3B1 Forest Land | D5: 3B1a Forest Land Remaining Forest Land | E5: Annual increase in carbon stocks in biomass | F5: GLC_FCS30D | G5: 2015 | H5: Tropical Dry | I5: 2339971 | J5: 10293999 | K5: -37744663 | L5: 1 | M5: 1 | N5: =K5*L5 -> -37744663 | O5: =K5*M5 -> -37744663
A6: 3 Agriculture, Forestry & Other Land Use | B6: 3B Land | C6: 3B1 Forest Land | D6: 3B1a Forest Land Remaining Forest Land | E6: Annual increase in carbon stocks in biomass | F6: GLC_FCS30D | G6: 2016 | H6: Tropical Dry | I6: 2390339 | J6: 10515577 | K6: -38557117 | L6: 1 | M6: 1 | N6: =K6*L6 -> -38557117 | O6: =K6*M6 -> -38557117
A7: 3 Agriculture, Forestry & Other Land Use | B7: 3B Land | C7: 3B1 Forest Land | D7: 3B1a Forest Land Remaining Forest Land | E7: Annual increase in carbon stocks in biomass | F7: GLC_FCS30D | G7: 2017 | H7: Tropical Dry | I7: 2389332 | J7: 10511148 | K7: -38540875 | L7: 1 | M7: 1 | N7: =K7*L7 -> -38540875 | O7: =K7*M7 -> -38540875
A8: 3 Agriculture, Forestry & Other Land Use | B8: 3B Land | C8: 3B1 Forest Land | D8: 3B1a Forest Land Remaining Forest Land | E8: Annual increase in carbon stocks in biomass | F8: GLC_FCS30D | G8: 2018 | H8: Tropical Dry | I8: 2362610 | J8: 10393596 | K8: -38109852 | L8: 1 | M8: 1 | N8: =K8*L8 -> -38109852 | O8: =K8*M8 -> -38109852
A9: 3 Agriculture, Forestry & Other Land Use | B9: 3B Land | C9: 3B1 Forest Land | D9: 3B1a Forest Land Remaining Forest Land | E9: Annual increase in carbon stocks in biomass | F9: GLC_FCS30D | G9: 2019 | H9: Tropical Dry | I9: 2323416 | J9: 10221171 | K9: -37477627 | L9: 1 | M9: 1 | N9: =K9*L9 -> -37477627 | O9: =K9*M9 -> -37477627
A10: 3 Agriculture, Forestry & Other Land Use | B10: 3B Land | C10: 3B1 Forest Land | D10: 3B1a Forest Land Remaining Forest Land | E10: Annual increase in carbon stocks in biomass | F10: GLC_FCS30D | G10: 2020 | H10: Tropical Dry | I10: 2250530 | J10: 9900533.3 | K10: -36301955 | L10: 1 | M10: 1 | N10: =K10*L10 -> -36301955 | O10: =K10*M10 -> -36301955
A11: 3 Agriculture, Forestry & Other Land Use | B11: 3B Land | C11: 3B1 Forest Land | D11: 3B1a Forest Land Remaining Forest Land | E11: Annual increase in carbon stocks in biomass | F11: GLC_FCS30D | G11: 2021 | H11: Tropical Dry | I11: 2236488 | J11: 9838758.5 | K11: -36075448 | L11: 1 | M11: 1 | N11: =K11*L11 -> -36075448 | O11: =K11*M11 -> -36075448
A12: 3 Agriculture, Forestry & Other Land Use | B12: 3B Land | C12: 3B1 Forest Land | D12: 3B1a Forest Land Remaining Forest Land | E12: Annual increase in carbon stocks in biomass | F12: GLC_FCS30D | G12: 2022 | H12: Tropical Dry | I12: 2225596 | J12: 9790842.9 | K12: -35899757 | L12: 1 | M12: 1 | N12: =K12*L12 -> -35899757 | O12: =K12*M12 -> -35899757
A13: 3 Agriculture, Forestry & Other Land Use | B13: 3B Land | C13: 3B1 Forest Land | D13: 3B1a Forest Land Remaining Forest Land | E13: Annual increase in carbon stocks in biomass | F13: GLC_FCS30D | G13: 2023 | H13: Tropical Dry | I13: 0 | J13: 0 | K13: 0 | L13: 1 | M13: 1 | N13: =K13*L13 -> 0 | O13: =K13*M13 -> 0
... A60: 3 Agriculture, Forestry & Other Land Use | B60: 3B Land | C60: 3B1 Forest Land | D60: 3B1b Land Converted to Forest Land | E60: Annual change in carbon stocks in dead organic matter due to land conversion | F60: GLC_FCS30D | G60: 2022 | H60: Tropical Dry | I60: 2225596 | J60: -1143.65 | K60: 4193.38 | L60: 1 | M60: 1 | N60: =K60*L60 -> 4193.38 | O60: =K60*M60 -> 4193.38
A61: 3 Agriculture, Forestry & Other Land Use | B61: 3B Land | C61: 3B1 Forest Land | D61: 3B1b Land Converted to Forest Land | E61: Annual change in carbon stocks in dead organic matter due to land conversion | F61: GLC_FCS30D | G61: 2023 | H61: Tropical Dry | I61: 0 | K61: 0 | L61: 1 | M61: 1 | N61: =K61*L61 -> 0 | O61: =K61*M61 -> 0
A62: 3 Agriculture, Forestry & Other Land Use | B62: 3B Land | C62: 3B1 Forest Land | D62: 3B1b Land Converted to Forest Land | E62: Annual change in carbon stocks in dead organic matter due to land conversion | F62: GLC_FCS30D | G62: 2012 | H62: Tropical Moist | I62: 253042 | J62: 712.42 | K62: -2612.22 | L62: 1 | M62: 1 | N62: =K62*L62 -> -2612.22 | O62: =K62*M62 -> -2612.22
A63: 3 Agriculture, Forestry & Other Land Use | B63: 3B Land | C63: 3B1 Forest Land | D63: 3B1b Land Converted to Forest Land | E63: Annual change in carbon stocks in dead organic matter due to land conversion | F63: GLC_FCS30D | G63: 2013 | H63: Tropical Moist | I63: 253606 | J63: 59.22 | K63: -217.15 | L63: 1 | M63: 1 | N63: =K63*L63 -> -217.15 | O63: =K63*M63 -> -217.15
A64: 3 Agriculture, Forestry & Other Land Use | B64: 3B Land | C64: 3B1 Forest Land | D64: 3B1b Land Converted to Forest Land | E64: Annual change in carbon stocks in dead organic matter due to land conversion | F64: GLC_FCS30D | G64: 2014 | H64: Tropical Moist | I64: 254066 | J64: 48.37 | K64: -177.37 | L64: 1 | M64: 1 | N64: =K64*L64 -> -177.37 | O64: =K64*M64 -> -177.37
A65: 3 Agriculture, Forestry & Other Land Use | B65: 3B Land | C65: 3B1 Forest Land | D65: 3B1b Land Converted to Forest Land | E65: Annual change in carbon stocks in dead organic matter due to land conversion | F65: GLC_FCS30D | G65: 2015 | H65: Tropical Moist | I65: 259997 | J65: 622.68 | K65: -2283.16 | L65: 1 | M65: 1 | N65: =K65*L65 -> -2283.16 | O65: =K65*M65 -> -2283.16
A66: 3 Agriculture, Forestry & Other Land Use | B66: 3B Land | C66: 3B1 Forest Land | D66: 3B1b Land Converted to Forest Land | E66: Annual change in carbon stocks in dead organic matter due to land conversion | F66: GLC_FCS30D | G66: 2016 | H66: Tropical Moist | I66: 265593 | J66: 587.63 | K66: -2154.63 | L66: 1 | M66: 1 | N66: =K66*L66 -> -2154.63 | O66: =K66*M66 -> -2154.63
A67: 3 Agriculture, Forestry & Other Land Use | B67: 3B Land | C67: 3B1 Forest Land | D67: 3B1b Land Converted to Forest Land | E67: Annual change in carbon stocks in dead organic matter due to land conversion | F67: GLC_FCS30D | G67: 2017 | H67: Tropical Moist | I67: 265481 | J67: -11.75 | K67: 43.07 | L67: 1 | M67: 1 | N67: =K67*L67 -> 43.07 | O67: =K67*M67 -> 43.07
A68: 3 Agriculture, Forestry & Other Land Use | B68: 3B Land | C68: 3B1 Forest Land | D68: 3B1b Land Converted to Forest Land | E68: Annual change in carbon stocks in dead organic matter due to land conversion | F68: GLC_FCS30D | G68: 2018 | H68: Tropical Moist | I68: 262512 | J68: -311.75 | K68: 1143.07 | L68: 1 | M68: 1 | N68: =K68*L68 -> 1143.07 | O68: =K68*M68 -> 1143.07
A69: 3 Agriculture, Forestry & Other Land Use | B69: 3B Land | C69: 3B1 Forest Land | D69: 3B1b Land Converted to Forest Land | E69: Annual change in carbon stocks in dead organic matter due to land conversion | F69: GLC_FCS30D | G69: 2019 | H69: Tropical Moist | I69: 258157 | J69: -457.27 | K69: 1676.66 | L69: 1 | M69: 1 | N69: =K69*L69 -> 1676.66 | O69: =K69*M69 -> 1676.66
A70: 3 Agriculture, Forestry & Other Land Use | B70: 3B Land | C70: 3B1 Forest Land | D70: 3B1b Land Converted to Forest Land | E70: Annual change in carbon stocks in dead organic matter due to land conversion | F70: GLC_FCS30D | G70: 2020 | H70: Tropical Moist | I70: 250059 | J70: -850.33 | K70: 3117.88 | L70: 1 | M70: 1 | N70: =K70*L70 -> 3117.88 | O70: =K70*M70 -> 3117.88
A71: 3 Agriculture, Forestry & Other Land Use | B71: 3B Land | C71: 3B1 Forest Land | D71: 3B1b Land Converted to Forest Land | E71: Annual change in carbon stocks in dead organic matter due to land conversion | F71: GLC_FCS30D | G71: 2021 | H71: Tropical Moist | I71: 248499 | J71: -163.83 | K71: 600.7 | L71: 1 | M71: 1 | N71: =K71*L71 -> 600.7 | O71: =K71*M71 -> 600.7
A72: 3 Agriculture, Forestry & Other Land Use | B72: 3B Land | C72: 3B1 Forest Land | D72: 3B1b Land Converted to Forest Land | E72: Annual change in carbon stocks in dead organic matter due to land conversion | F72: GLC_FCS30D | G72: 2022 | H72: Tropical Moist | I72: 247288 | J72: -127.07 | K72: 465.93 | L72: 1 | M72: 1 | N72: =K72*L72 -> 465.93 | O72: =K72*M72 -> 465.93
A73: 3 Agriculture, Forestry & Other Land Use | B73: 3B Land | C73: 3B1 Forest Land | D73: 3B1b Land Converted to Forest Land | E73: Annual change in carbon stocks in dead organic matter due to land conversion | F73: GLC_FCS30D | G73: 2023 | H73: Tropical Moist | I73: 0 | K73: 0 | L73: 1 | M73: 1 | N73: =K73*L73 -> 0 | O73: =K73*M73 -> 0

Sheet State_Graphs
A1: Emission (Ton yr^-1)/(Conversion of C to CO2) | L1: Annual Change in Carbon Stock(tonnes C yr-1)
A2: Year | B2: Tropical Dry | C2: Tropical Moist | D2: Tropical Dry | E2: Tropical Moist | F2: Tropical Dry | G2: Tropical Moist | H2: Tropical Dry | I2: Tropical Moist | J2: Total | L2: Year | M2: Tropical Dry | N2: Tropical Moist | O2: Tropical Dry | P2: Tropical Moist | Q2: Tropical Dry | R2: Tropical Moist | S2: Tropical Dry | T2: Tropical Moist | U2: Total
A3: 2015 | B3: -37772208 | C3: -4842590.7 | D3: -37772208 | E3: -4842590.7 | F3: -901546.15 | G3: -100171.79 | H3: 1351945.2 | I3: 225467.44 | J3: =SUM(B3:I3) -> -84653902 | L3: 2015 | M3: 10301511 | N3: 1320706.6 | O3: 10301511 | P3: 1320706.6 | Q3: 245876.22 | R3: 27319.58 | S3: -368712.32 | T3: -61491.119 | U3: =SUM(M3:T3) -> 23087428
A4: 2016 | B4: -38584200 | C4: -4946692.3 | D4: -811992.29 | E4: -104101.58 | F4: -19380.612 | G4: -2153.4014 | H4: 29062.878 | I4: 4846.8922 | J4: =SUM(B4:I4) -> -44434610 | L4: 2016 | M4: 10522964 | N4: 1349097.9 | O4: 221452.44 | P4: 28391.339 | Q4: 5285.6216 | R4: 587.29129 | S4: -7926.2394 | T4: -1321.8797 | U4: =SUM(M4:T4) -> 12118530
A5: 2017 | B5: -38563562 | C5: -4944046.5 | D5: 20637.666 | E5: 2645.8547 | F5: 492.57933 | G5: 54.731036 | H5: -738.66462 | I5: -123.18903 | J5: =SUM(B5:I5) -> -43484640 | L5: 2017 | M5: 10517335 | N5: 1348376.3 | O5: -5628.4545 | P5: -721.59673 | Q5: -134.33982 | R5: -14.926646 | S5: 201.45399 | T5: 33.597009 | U5: =SUM(M5:T5) -> 11859447
A6: 2018 | B6: -38126400 | C6: -4888000.1 | D6: 437161.93 | E6: 56046.402 | F6: 10434.171 | G6: 1159.3523 | H6: -15646.927 | I6: -2609.4789 | J6: =SUM(B6:I6) -> -42527855 | L6: 2018 | M6: 10398109 | N6: 1333090.9 | O6: -119225.98 | P6: -15285.382 | Q6: -2845.6829 | R6: -316.18699 | S6: 4267.3436 | T6: 711.67608 | U6: =SUM(M6:T6) -> 11598506
A7: 2019 | B7: -37493278 | C7: -4806830.6 | D7: 633122.1 | E7: 81169.5 | F7: 15111.343 | G7: 1679.0381 | H7: -22660.745 | I7: -3779.1918 | J7: =SUM(B7:I7) -> -41595467 | L7: 2019 | M7: 10225440 | N7: 1310953.8 | O7: -172669.66 | P7: -22137.136 | Q7: -4121.2754 | R7: -457.91949 | S7: 6180.2031 | T7: 1030.6887 | U7: =SUM(M7:T7) -> 11344218
A8: 2020 | B8: -36319834 | C8: -4656389 | D8: 1173444.1 | E8: 150441.55 | F8: 28007.735 | G8: 3111.9705 | H8: -41999.981 | I8: -7004.4469 | J8: =SUM(B8:I8) -> -39670222 | L8: 2020 | M8: 9905409.3 | N8: 1269924.3 | O8: -320030.2 | P8: -41029.513 | Q8: -7638.4731 | R8: -848.71923 | S8: 11454.54 | T8: 1910.3037 | U8: =SUM(M8:T8) -> 10819152
A9: 2021 | B9: -36096359 | C9: -4627738.3 | D9: 223475.75 | E9: 28650.738 | F9: 5333.9139 | G9: 592.6571 | H9: -7998.6578 | I9: -1333.9571 | J9: =SUM(B9:I9) -> -40475376 | L9: 2021 | M9: 9844461.4 | N9: 1262110.4 | O9: -60947.933 | P9: -7813.8375 | Q9: -1454.7038 | R9: -161.63376 | S9: 2181.4521 | T9: 363.80649 | U9: =SUM(M9:T9) -> 11038739
A10: 2022 | B10: -35920331 | C10: -4605170.6 | D10: 176027.69 | E10: 22567.652 | F10: 4201.4246 | G10: 466.82495 | H10: -6300.3937 | I10: -1050.7332 | J10: =SUM(B10:I10) -> -40329589 | L10: 2022 | M10: 9796453.9 | N10: 1255955.6 | O10: -48007.551 | P10: -6154.8142 | Q10: -1145.8431 | R10: -127.3159 | S10: 1718.2892 | T10: 286.56359 | U10: =SUM(M10:T10) -> 10998979
A13: CO2e GWP20/GWP100(tonnes CO₂e/year) | L13: Annual Change in Crabon Stocks(tonnes C/year)
A14: Year | B14: Emissions(tonnes CO₂e/year) | L14: Year | M14: Forest Land
A15: 2015 | B15: =J3 -> -84653902 | L15: 2015 | M15: =U3 -> 23087428
A16: 2016 | B16: =J4 -> -44434610 | L16: 2016 | M16: =U4 -> 12118530
A17: 2017 | B17: =J5 -> -43484640 | L17: 2017 | M17: =U5 -> 11859447
A18: 2018 | B18: =J6 -> -42527855 | L18: 2018 | M18: =U6 -> 11598506
A19: 2019 | B19: =J7 -> -41595467 | L19: 2019 | M19: =U7 -> 11344218
A20: 2020 | B20: =J8 -> -39670222 | L20: 2020 | M20: =U8 -> 10819152
A21: 2021 | B21: =J9 -> -40475376 | L21: 2021 | M21: =U9 -> 11038739
A22: 2022 | B22: =J10 -> -40329589 | L22: 2022 | M22: =U10 -> 10998979

Sheet Dist_Wise Restructured
A1: Sector | B1: Sub- Sector | C1: Sub- Sector | D1: Sub- Sector | E1: Category | F1: Data Source | G1: District | H1: Year | I1: Climate Type | J1: Activity Data(ha)(Area of Forest Land) | K1: Annual Change in Carbon Stock(tonnes C yr-1) | L1: Emission (Ton yr^-1)/(Conversion of C to CO2) | M1: GWP20 | N1: GWP100 | O1: CO2e GWP20 | P1: CO2e GWP100
A2: 3 Agriculture, Forestry & Other Land Use | B2: 3B Land | C2: 3B1 Forest Land | D2: 3B1a Forest Land Remaining Forest Land | E2: Annual increase in carbon stocks in biomass | F2: GLC_FCS30D | G2: Ahmadabad Total | H2: 2012 | I2: Tropical Dry | J2: 6770 | K2: 29781.98 | L2: -109200.58 | M2: 1 | N2: 1 | O2: =L2*M2 -> -109200.58 | P2: =L2*N2 -> -109200.58
A3: 3 Agriculture, Forestry & Other Land Use | B3: 3B Land | C3: 3B1 Forest Land | D3: 3B1a Forest Land Remaining Forest Land | E3: Annual increase in carbon stocks in biomass | F3: GLC_FCS30D | G3: Ahmadabad Total | H3: 2013 | I3: Tropical Dry | J3: 7056 | K3: 31039.86 | L3: -113812.83 | M3: 1 | N3: 1 | O3: =L3*M3 -> -113812.83 | P3: =L3*N3 -> -113812.83
A4: 3 Agriculture, Forestry & Other Land Use | B4: 3B Land | C4: 3B1 Forest Land | D4: 3B1a Forest Land Remaining Forest Land | E4: Annual increase in carbon stocks in biomass | F4: GLC_FCS30D | G4: Ahmadabad Total | H4: 2014 | I4: Tropical Dry | J4: 6759 | K4: 29733.67 | L4: -109023.44 | M4: 1 | N4: 1 | O4: =L4*M4 -> -109023.44 | P4: =L4*N4 -> -109023.44
A5: 3 Agriculture, Forestry & Other Land Use | B5: 3B Land | C5: 3B1 Forest Land | D5: 3B1a Forest Land Remaining Forest Land | E5: Annual increase in carbon stocks in biomass | F5: GLC_FCS30D | G5: Ahmadabad Total | H5: 2015 | I5: Tropical Dry | J5: 6927 | K5: 30472.54 | L5: -111732.65 | M5: 1 | N5: 1 | O5: =L5*M5 -> -111732.65 | P5: =L5*N5 -> -111732.65
A6: 3 Agriculture, Forestry & Other Land Use | B6: 3B Land | C6: 3B1 Forest Land | D6: 3B1a Forest Land Remaining Forest Land | E6: Annual increase in carbon stocks in biomass | F6: GLC_FCS30D | G6: Ahmadabad Total | H6: 2016 | I6: Tropical Dry | J6: 6519 | K6: 28676.44 | L6: -105146.94 | M6: 1 | N6: 1 | O6: =L6*M6 -> -105146.94 | P6: =L6*N6 -> -105146.94
A7: 3 Agriculture, Forestry & Other Land Use | B7: 3B Land | C7: 3B1 Forest Land | D7: 3B1a Forest Land Remaining Forest Land | E7: Annual increase in carbon stocks in biomass | F7: GLC_FCS30D | G7: Ahmadabad Total | H7: 2017 | I7: Tropical Dry | J7: 5917 | K7: 26031.9 | L7: -95450.31 | M7: 1 | N7: 1 | O7: =L7*M7 -> -95450.31 | P7: =L7*N7 -> -95450.31
A8: 3 Agriculture, Forestry & Other Land Use | B8: 3B Land | C8: 3B1 Forest Land | D8: 3B1a Forest Land Remaining Forest Land | E8: Annual increase in carbon stocks in biomass | F8: GLC_FCS30D | G8: Ahmadabad Total | H8: 2018 | I8: Tropical Dry | J8: 5497 | K8: 24181.81 | L8: -88666.64 | M8: 1 | N8: 1 | O8: =L8*M8 -> -88666.64 | P8: =L8*N8 -> -88666.64
A9: 3 Agriculture, Forestry & Other Land Use | B9: 3B Land | C9: 3B1 Forest Land | D9: 3B1a Forest Land Remaining Forest Land | E9: Annual increase in carbon stocks in biomass | F9: GLC_FCS30D | G9: Ahmadabad Total | H9: 2019 | I9: Tropical Dry | J9: 5583 | K9: 24562.88 | L9: -90063.9 | M9: 1 | N9: 1 | O9: =L9*M9 -> -90063.9 | P9: =L9*N9 -> -90063.9
A10: 3 Agriculture, Forestry & Other Land Use | B10: 3B Land | C10: 3B1 Forest Land | D10: 3B1a Forest Land Remaining Forest Land | E10: Annual increase in carbon stocks in biomass | F10: GLC_FCS30D | G10: Ahmadabad Total | H10: 2020 | I10: Tropical Dry | J10: 4331 | K10: 19051.51 | L10: -69855.54 | M10: 1 | N10: 1 | O10: =L10*M10 -> -69855.54 | P10: =L10*N10 -> -69855.54
A11: 3 Agriculture, Forestry & Other Land Use | B11: 3B Land | C11: 3B1 Forest Land | D11: 3B1a Forest Land Remaining Forest Land | E11: Annual increase in carbon stocks in biomass | F11: GLC_FCS30D | G11: Ahmadabad Total | H11: 2021 | I11: Tropical Dry | J11: 4045 | K11: 17793.49 | L11: -65242.79 | M11: 1 | N11: 1 | O11: =L11*M11 -> -65242.79 | P11: =L11*N11 -> -65242.79
A12: 3 Agriculture, Forestry & Other Land Use | B12: 3B Land | C12: 3B1 Forest Land | D12: 3B1a Forest Land Remaining Forest Land | E12: Annual increase in carbon stocks in biomass | F12: GLC_FCS30D | G12: Ahmadabad Total | H12: 2022 | I12: Tropical Dry | J12: 4358 | K12: 19171.2 | L12: -70294.39 | M12: 1 | N12: 1 | O12: =L12*M12 -> -70294.39 | P12: =L12*N12 -> -70294.39
A13: 3 Agriculture, Forestry & Other Land Use | B13: 3B Land | C13: 3B1 Forest Land | D13: 3B1a Forest Land Remaining Forest Land | E13: Annual increase in carbon stocks in biomass | F13: GLC_FCS30D | G13: Amreli Total | H13: 2011 | I13: Tropical Dry | J13: 54760 | K13: 240900.83 | L13: -883303.05 | M13: 1 | N13: 1 | O13: =L13*M13 -> -883303.05 | P13: =L13*N13 -> -883303.05
... A802: 3 Agriculture, Forestry & Other Land Use | B802: 3B Land | C802: 3B1 Forest Land | D802: 3B1b Land Converted to Forest Land | E802: Annual increase in carbon stocks in biomass | F802: GLC_FCS30D | G802: Ahmadabad Total | H802: 2022 | I802: Tropical Dry | J802: 313 | K802: 1377.71 | L802: -5051.59 | M802: 1 | N802: 1 | O802: =L802*M802 -> -5051.59 | P802: =L802*N802 -> -5051.59
A803: 3 Agriculture, Forestry & Other Land Use | B803: 3B Land | C803: 3B1 Forest Land | D803: 3B1b Land Converted to Forest Land | E803: Annual increase in carbon stocks in biomass | F803: GLC_FCS30D | G803: Amreli Total | H803: 2011 | I803: Tropical Dry | K803: 0 | L803: 0 | M803: 1 | N803: 1 | O803: =L803*M803 -> 0 | P803: =L803*N803 -> 0
A804: 3 Agriculture, Forestry & Other Land Use | B804: 3B Land | C804: 3B1 Forest Land | D804: 3B1b Land Converted to Forest Land | E804: Annual increase in carbon stocks in biomass | F804: GLC_FCS30D | G804: Amreli Total | H804: 2012 | I804: Tropical Dry | J804: -4260 | K804: -18740.26 | L804: 68714.27 | M804: 1 | N804: 1 | O804: =L804*M804 -> 68714.27 | P804: =L804*N804 -> 68714.27
A805: 3 Agriculture, Forestry & Other Land Use | B805: 3B Land | C805: 3B1 Forest Land | D805: 3B1b Land Converted to Forest Land | E805: Annual increase in carbon stocks in biomass | F805: GLC_FCS30D | G805: Amreli Total | H805: 2013 | I805: Tropical Dry | J805: -1647 | K805: -7244.61 | L805: 26563.55 | M805: 1 | N805: 1 | O805: =L805*M805 -> 26563.55 | P805: =L805*N805 -> 26563.55
A806: 3 Agriculture, Forestry & Other Land Use | B806: 3B Land | C806: 3B1 Forest Land | D806: 3B1b Land Converted to Forest Land | E806: Annual increase in carbon stocks in biomass | F806: GLC_FCS30D | G806: Amreli Total | H806: 2014 | I806: Tropical Dry | J806: 2578 | K806: 11342.34 | L806: -41588.57 | M806: 1 | N806: 1 | O806: =L806*M806 -> -41588.57 | P806: =L806*N806 -> -41588.57
A807: 3 Agriculture, Forestry & Other Land Use | B807: 3B Land | C807: 3B1 Forest Land | D807: 3B1b Land Converted to Forest Land | E807: Annual increase in carbon stocks in biomass | F807: GLC_FCS30D | G807: Amreli Total | H807: 2015 | I807: Tropical Dry | J807: 1691 | K807: 7437.86 | L807: -27272.16 | M807: 1 | N807: 1 | O807: =L807*M807 -> -27272.16 | P807: =L807*N807 -> -27272.16
A808: 3 Agriculture, Forestry & Other Land Use | B808: 3B Land | C808: 3B1 Forest Land | D808: 3B1b Land Converted to Forest Land | E808: Annual increase in carbon stocks in biomass | F808: GLC_FCS30D | G808: Amreli Total | H808: 2016 | I808: Tropical Dry | J808: -131 | K808: -576.61 | L808: 2114.23 | M808: 1 | N808: 1 | O808: =L808*M808 -> 2114.23 | P808: =L808*N808 -> 2114.23
A809: 3 Agriculture, Forestry & Other Land Use | B809: 3B Land | C809: 3B1 Forest Land | D809: 3B1b Land Converted to Forest Land | E809: Annual increase in carbon stocks in biomass | F809: GLC_FCS30D | G809: Amreli Total | H809: 2017 | I809: Tropical Dry | J809: -2601 | K809: -11444.38 | L809: 41962.73 | M809: 1 | N809: 1 | O809: =L809*M809 -> 41962.73 | P809: =L809*N809 -> 41962.73
A810: 3 Agriculture, Forestry & Other Land Use | B810: 3B Land | C810: 3B1 Forest Land | D810: 3B1b Land Converted to Forest Land | E810: Annual increase in carbon stocks in biomass | F810: GLC_FCS30D | G810: Amreli Total | H810: 2018 | I810: Tropical Dry | J810: -1165 | K810: -5123.26 | L810: 18785.3 | M810: 1 | N810: 1 | O810: =L810*M810 -> 18785.3 | P810: =L810*N810 -> 18785.3
A811: 3 Agriculture, Forestry & Other Land Use | B811: 3B Land | C811: 3B1 Forest Land | D811: 3B1b Land Converted to Forest Land | E811: Annual increase in carbon stocks in biomass | F811: GLC_FCS30D | G811: Amreli Total | H811: 2019 | I811: Tropical Dry | J811: 2598 | K811: 11427.35 | L811: -41900.27 | M811: 1 | N811: 1 | O811: =L811*M811 -> -41900.27 | P811: =L811*N811 -> -41900.27
A812: 3 Agriculture, Forestry & Other Land Use | B812: 3B Land | C812: 3B1 Forest Land | D812: 3B1b Land Converted to Forest Land | E812: Annual increase in carbon stocks in biomass | F812: GLC_FCS30D | G812: Amreli Total | H812: 2020 | I812: Tropical Dry | J812: 3088 | K812: 13586.83 | L812: -49818.39 | M812: 1 | N812: 1 | O812: =L812*M812 -> -49818.39 | P812: =L812*N812 -> -49818.39
A813: 3 Agriculture, Forestry & Other Land Use | B813: 3B Land | C813: 3B1 Forest Land | D813: 3B1b Land Converted to Forest Land | E813: Annual increase in carbon stocks in biomass | F813: GLC_FCS30D | G813: Amreli Total | H813: 2021 | I813: Tropical Dry | J813: 2028 | K813: 8922.23 | L813: -32714.84 | M813: 1 | N813: 1 | O813: =L813*M813 -> -32714.84 | P813: =L813*N813 -> -32714.84
A814: 3 Agriculture, Forestry & Other Land Use | B814: 3B Land | C814: 3B1 Forest Land | D814: 3B1b Land Converted to Forest Land | E814: Annual increase in carbon stocks in biomass | F814: GLC_FCS30D | G814: Amreli Total | H814: 2022 | I814: Tropical Dry | J814: -1102 | K814: -4848.86 | L814: 17779.17 | M814: 1 | N814: 1 | O814: =L814*M814 -> 17779.17 | P814: =L814*N814 -> 17779.17
A815: 3 Agriculture, Forestry & Other Land Use | B815: 3B Land | C815: 3B1 Forest Land | D815: 3B1b Land Converted to Forest Land | E815: Annual increase in carbon stocks in biomass | F815: GLC_FCS30D | G815: Anand Total | H815: 2011 | I815: Tropical Dry | K815: 0 | L815: 0 | M815: 1 | N815: 1 | O815: =L815*M815 -> 0 | P815: =L815*N815 -> 0
A816: 3 Agriculture, Forestry & Other Land Use | B816: 3B Land | C816: 3B1 Forest Land | D816: 3B1b Land Converted to Forest Land | E816: Annual increase in carbon stocks in biomass | F816: GLC_FCS30D | G816: Anand Total | H816: 2012 | I816: Tropical Dry | J816: 87 | K816: 384.9 | L816: -1411.3 | M816: 1 | N816: 1 | O816: =L816*M816 -> -1411.3 | P816: =L816*N816 -> -1411.3
A817: 3 Agriculture, Forestry & Other Land Use | B817: 3B Land | C817: 3B1 Forest Land | D817: 3B1b Land Converted to Forest Land | E817: Annual increase in carbon stocks in biomass | F817: GLC_FCS30D | G817: Anand Total | H817: 2013 | I817: Tropical Dry | J817: 395 | K817: 1737.94 | L817: -6372.44 | M817: 1 | N817: 1 | O817: =L817*M817 -> -6372.44 | P817: =L817*N817 -> -6372.44
A818: 3 Agriculture, Forestry & Other Land Use | B818: 3B Land | C818: 3B1 Forest Land | D818: 3B1b Land Converted to Forest Land | E818: Annual increase in carbon stocks in biomass | F818: GLC_FCS30D | G818: Anand Total | H818: 2014 | I818: Tropical Dry | J818: -255 | K818: -1120.39 | L818: 4108.11 | M818: 1 | N818: 1 | O818: =L818*M818 -> 4108.11 | P818: =L818*N818 -> 4108.11
A819: 3 Agriculture, Forestry & Other Land Use | B819: 3B Land | C819: 3B1 Forest Land | D819: 3B1b Land Converted to Forest Land | E819: Annual increase in carbon stocks in biomass | F819: GLC_FCS30D | G819: Anand Total | H819: 2015 | I819: Tropical Dry | J819: -300 | K819: -1317.61 | L819: 4831.24 | M819: 1 | N819: 1 | O819: =L819*M819 -> 4831.24 | P819: =L819*N819 -> 4831.24
A820: 3 Agriculture, Forestry & Other Land Use | B820: 3B Land | C820: 3B1 Forest Land | D820: 3B1b Land Converted to Forest Land | E820: Annual increase in carbon stocks in biomass | F820: GLC_FCS30D | G820: Anand Total | H820: 2016 | I820: Tropical Dry | J820: 126 | K820: 553.78 | L820: -2030.52 | M820: 1 | N820: 1 | O820: =L820*M820 -> -2030.52 | P820: =L820*N820 -> -2030.52
A821: 3 Agriculture, Forestry & Other Land Use | B821: 3B Land | C821: 3B1 Forest Land | D821: 3B1b Land Converted to Forest Land | E821: Annual increase in carbon stocks in biomass | F821: GLC_FCS30D | G821: Anand Total | H821: 2017 | I821: Tropical Dry | J821: 20 | K821: 86.52 | L821: -317.26 | M821: 1 | N821: 1 | O821: =L821*M821 -> -317.26 | P821: =L821*N821 -> -317.26
A822: 3 Agriculture, Forestry & Other Land Use | B822: 3B Land | C822: 3B1 Forest Land | D822: 3B1b Land Converted to Forest Land | E822: Annual increase in carbon stocks in biomass | F822: GLC_FCS30D | G822: Anand Total | H822: 2018 | I822: Tropical Dry | J822: -478 | K822: -2100.65 | L822: 7702.38 | M822: 1 | N822: 1 | O822: =L822*M822 -> 7702.38 | P822: =L822*N822 -> 7702.38
A823: 3 Agriculture, Forestry & Other Land Use | B823: 3B Land | C823: 3B1 Forest Land | D823: 3B1b Land Converted to Forest Land | E823: Annual increase in carbon stocks in biomass | F823: GLC_FCS30D | G823: Anand Total | H823: 2019 | I823: Tropical Dry | J823: -774 | K823: -3403.15 | L823: 12478.21 | M823: 1 | N823: 1 | O823: =L823*M823 -> 12478.21 | P823: =L823*N823 -> 12478.21
A824: 3 Agriculture, Forestry & Other Land Use | B824: 3B Land | C824: 3B1 Forest Land | D824: 3B1b Land Converted to Forest Land | E824: Annual increase in carbon stocks in biomass | F824: GLC_FCS30D | G824: Anand Total | H824: 2020 | I824: Tropical Dry | J824: -957 | K824: -4209.73 | L824: 15435.67 | M824: 1 | N824: 1 | O824: =L824*M824 -> 15435.67 | P824: =L824*N824 -> 15435.67
A825: 3 Agriculture, Forestry & Other Land Use | B825: 3B Land | C825: 3B1 Forest Land | D825: 3B1b Land Converted to Forest Land | E825: Annual increase in carbon stocks in biomass | F825: GLC_FCS30D | G825: Anand Total | H825: 2021 | I825: Tropical Dry | J825: -241 | K825: -1059.62 | L825: 3885.28 | M825: 1 | N825: 1 | O825: =L825*M825 -> 3885.28 | P825: =L825*N825 -> 3885.28
A826: 3 Agriculture, Forestry & Other Land Use | B826: 3B Land | C826: 3B1 Forest Land | D826: 3B1b Land Converted to Forest Land | E826: Annual increase in carbon stocks in biomass | F826: GLC_FCS30D | G826: Anand Total | H826: 2022 | I826: Tropical Dry | J826: 160 | K826: 704.5 | L826: -2583.17 | M826: 1 | N826: 1 | O826: =L826*M826 -> -2583.17 | P826: =L826*N826 -> -2583.17
A827: 3 Agriculture, Forestry & Other Land Use | B827: 3B Land | C827: 3B1 Forest Land | D827: 3B1b Land Converted to Forest Land | E827: Annual increase in carbon stocks in biomass | F827: GLC_FCS30D | G827: Arvalli Total | H827: 2011 | I827: Tropical Dry | K827: 0 | L827: 0 | M827: 1 | N827: 1 | O827: =L827*M827 -> 0 | P827: =L827*N827 -> 0
A828: 3 Agriculture, Forestry & Other Land Use | B828: 3B Land | C828: 3B1 Forest Land | D828: 3B1b Land Converted to Forest Land | E828: Annual increase in carbon stocks in biomass | F828: GLC_FCS30D | G828: Arvalli Total | H828: 2012 | I828: Tropical Dry | J828: 9939 | K828: 43723.72 | L828: -160320.31 | M828: 1 | N828: 1 | O828: =L828*M828 -> -160320.31 | P828: =L828*N828 -> -160320.31
...

Sheet Dist_Wise Graphs
B1: Emission (Ton yr^-1)/(Conversion of C to CO2) | M1: Annual Change in Carbon Stock(tonnes C yr-1)
A2: District | B2: Year | C2: Tropical Dry | D2: Tropical Moist | E2: Tropical Dry | F2: Tropical Moist | G2: Tropical Dry | H2: Tropical Moist | I2: Tropical Dry | J2: Tropical Moist | K2: Total | M2: Year | N2: Tropical Dry | O2: Tropical Moist | P2: Tropical Dry | Q2: Tropical Moist | R2: Tropical Dry | S2: Tropical Moist | T2: Tropical Dry | U2: Tropical Moist | V2: Total
A3: Ahmadabad Total | B3: 2015 | C3: -111732.65 | D3: -14324.699 | E3: 0 | F3: 0 | G3: 0 | H3: 0 | I3: 0 | J3: 0 | K3: =SUM(C3:J3) -> -126057.35 | M3: 2015 | N3: 10301511 | O3: 1320706.6 | P3: 10301511 | Q3: 1320706.6 | R3: 245876.22 | S3: 27319.58 | T3: -368712.32 | U3: -61491.119 | V3: =SUM(N3:U3) -> 23087428
A4: Amreli Total | B4: 2015 | C4: -856885.95 | D4: -109857.17 | E4: -745153.3 | F4: -95532.475 | G4: -17785.301 | H4: -1976.1446 | I4: 26670.572 | J4: 4447.9213 | K4: =SUM(C4:J4) -> -1796071.9 | M4: 2016 | N4: 10522964 | O4: 1349097.9 | P4: 221452.44 | Q4: 28391.339 | R4: 5285.6216 | S4: 587.29129 | T4: -7926.2394 | U4: -1321.8797 | V4: =SUM(N4:U4) -> 12118530
A5: Anand Total | B5: 2015 | C5: -153119.1 | D5: -19630.653 | E5: 703766.86 | F5: 90226.52 | G5: 16797.49 | H5: 1866.3878 | I5: -25189.266 | J5: -4200.88 | K5: =SUM(C5:J5) -> 610517.36 | M5: 2017 | N5: 10517335 | O5: 1348376.3 | P5: -5628.4545 | Q5: -721.59673 | R5: -134.33982 | S5: -14.926646 | T5: 201.45399 | U5: 33.597009 | V5: =SUM(N5:U5) -> 11859447
A6: Arvalli Total | B6: 2015 | C6: -2321915.7 | D6: -297681.5 | E6: -2168796.6 | F6: -278050.85 | G6: -51764.785 | H6: -5751.6428 | I6: 77625.7 | J6: 12945.841 | K6: =SUM(C6:J6) -> -5033389.5 | M6: 2018 | N6: 10398109 | O6: 1333090.9 | P6: -119225.98 | Q6: -15285.382 | R6: -2845.6829 | S6: -316.18699 | T6: 4267.3436 | U6: 711.67608 | V6: =SUM(N6:U6) -> 11598506
A7: Banas_Kantha Total | B7: 2015 | C7: -1430713.9 | D7: -183424.85 | E7: 891201.84 | F7: 114256.65 | G7: 21271.184 | H7: 2363.4649 | I7: -31897.951 | J7: -5319.7048 | K7: =SUM(C7:J7) -> -622263.22 | M7: 2019 | N7: 10225440 | O7: 1310953.8 | P7: -172669.66 | Q7: -22137.136 | R7: -4121.2754 | S7: -457.91949 | T7: 6180.2031 | U7: 1030.6887 | V7: =SUM(N7:U7) -> 11344218
A8: Bharuch Total | B8: 2015 | C8: -301657.94 | D8: -38674.095 | E8: 1129055.9 | F8: 144750.76 | G8: 26948.279 | H8: 2994.2533 | I8: -40411.238 | J8: -6739.488 | K8: =SUM(C8:J8) -> 916266.43 | M8: 2020 | N8: 9905409.3 | O8: 1269924.3 | P8: -320030.2 | Q8: -41029.513 | R8: -7638.4731 | S8: -848.71923 | T8: 11454.54 | U8: 1910.3037 | V8: =SUM(N8:U8) -> 10819152
A9: Bhavnagar Total | B9: 2015 | C9: -448483.18 | D9: -57497.844 | E9: -146825.24 | F9: -18823.749 | G9: -3504.4213 | H9: -389.38014 | I9: 5255.1779 | J9: 876.41979 | K9: =SUM(C9:J9) -> -669392.22 | M9: 2021 | N9: 9844461.4 | O9: 1262110.4 | P9: -60947.933 | Q9: -7813.8375 | R9: -1454.7038 | S9: -161.63376 | T9: 2181.4521 | U9: 363.80649 | V9: =SUM(N9:U9) -> 11038739
A10: Botad Total | B10: 2015 | C10: -53750.222 | D10: -6891.0541 | E10: 394732.96 | F10: 50606.79 | G10: 9421.4768 | H10: 1046.8308 | I10: -14128.306 | J10: -2356.2146 | K10: =SUM(C10:J10) -> 378682.26 | M10: 2022 | N10: 9796453.9 | O10: 1255955.6 | P10: -48007.551 | Q10: -6154.8142 | R10: -1145.8431 | S10: -127.3159 | T10: 1718.2892 | U10: 286.56359 | V10: =SUM(N10:U10) -> 10998979
A11: Chhotaudepur Total | B11: 2015 | C11: -2555947.8 | D11: -327685.61 | E11: -2502197.6 | F11: -320794.56 | G11: -59722.392 | H11: -6635.8213 | I11: 89558.808 | J11: 14935.957 | K11: =SUM(C11:J11) -> -5668489
A12: Dahod Total | B12: 2015 | C12: -2231610.4 | D12: -286103.9 | E12: 324337.39 | F12: 41581.716 | G12: 7741.277 | H12: 860.14189 | I12: -11608.704 | J12: -1936.0139 | K12: =SUM(C12:J12) -> -2156738.5
A13: Dangs Total | B13: 2015 | C13: -2454408.3 | D13: -314667.73 | E13: -222797.86 | F13: -28563.828 | G13: -5317.734 | H13: -590.85933 | I13: 7974.3946 | J13: 1329.9107 | K13: =SUM(C13:J13) -> -3017042 | M13: Annual Change in Crabon Stocks(tonnes C/year)
A14: Devbhumi Dwarka Total | B14: 2015 | C14: -67829.34 | D14: -8696.0692 | E14: 2386578.9 | F14: 305971.66 | G14: 56962.809 | H14: 6329.2009 | I14: -85420.579 | J14: -14245.814 | K14: =SUM(C14:J14) -> 2579650.8 | M14: Year | N14: Forest Land
A15: Gandhinagar Total | B15: 2015 | C15: -672829.29 | D15: -86260.165 | E15: -604999.95 | F15: -77564.096 | G15: -14440.124 | H15: -1604.4582 | I15: 21654.195 | J15: 3611.3268 | K15: =SUM(C15:J15) -> -1432432.6 | M15: 2015 | N15: =V3 -> 23087428
A16: Gir Somnath Total | B16: 2015 | C16: -2406582.1 | D16: -308536.17 | E16: -1733752.8 | F16: -222276 | G16: -41381.171 | H16: -4597.9079 | I16: 62054.587 | J16: 10349.006 | K16: =SUM(C16:J16) -> -4644722.6 | M16: 2016 | N16: =V4 -> 12118530
A17: Jamnagar Total | B17: 2015 | C17: -222682.33 | D17: -28549.017 | E17: 2183899.8 | F17: 279987.15 | G17: 52125.268 | H17: 5791.6964 | I17: -78166.274 | J17: -13035.994 | K17: =SUM(C17:J17) -> 2179370.3 | M17: 2017 | N17: =V5 -> 11859447
A18: Junagadh Total | B18: 2015 | C18: -3808122.5 | D18: -488220.83 | E18: -3585440.1 | F18: -459671.81 | G18: -85577.199 | H18: -9508.5777 | I18: 128330.29 | J18: 21401.979 | K18: =SUM(C18:J18) -> -8286808.7 | M18: 2018 | N18: =V6 -> 11598506
A19: Kachchh Total | B19: 2015 | C19: -117619.96 | D19: -15079.481 | E19: 3690502.5 | F19: 473141.35 | G19: 88084.825 | H19: 9787.2028 | I19: -132090.69 | J19: -22029.111 | K19: =SUM(C19:J19) -> 3974696.6 | M19: 2019 | N19: =V7 -> 11344218
A20: Kheda Total | B20: 2015 | C20: -745749.88 | D20: -95608.959 | E20: -628129.92 | F20: -80529.477 | G20: -14992.19 | H20: -1665.7989 | I20: 22482.065 | J20: 3749.3928 | K20: =SUM(C20:J20) -> -1540444.8 | M20: 2020 | N20: =V8 -> 10819152
A21: Mahesana Total | B21: 2015 | C21: -574732.33 | D21: -73683.633 | E21: 171017.54 | F21: 21925.326 | G21: 4081.8426 | H21: 453.53807 | I21: -6121.0704 | J21: -1020.8269 | K21: =SUM(C21:J21) -> -458079.61 | M21: 2021 | N21: =V9 -> 11038739
A22: Mahisagar Total | B22: 2015 | C22: -1950662.5 | D22: -250084.94 | E22: -1375930.2 | F22: -176401.31 | G22: -32840.669 | H22: -3648.9632 | I22: 49247.378 | J22: 8213.1142 | K22: =SUM(C22:J22) -> -3732108.1 | M22: 2022 | N22: =V10 -> 10998979
A23: Morbi Total | B23: 2015 | C23: -535730.53 | D23: -68683.401 | E23: 1414932 | F23: 181401.54 | G23: 33771.563 | H23: 3752.3959 | I23: -50643.333 | J23: -8445.9213 | K23: =SUM(C23:J23) -> 970354.32
A24: Narmada Total | B24: 2015 | C24: -1910600.7 | D24: -244948.81 | E24: -1374870.2 | F24: -176265.4 | G24: -32815.368 | H24: -3646.152 | I24: 49209.437 | J24: 8206.7867 | K24: =SUM(C24:J24) -> -3685730.3
A25: Navsari Total | B25: 2015 | C25: -1078716.7 | D25: -138297.01 | E25: 831884.02 | F25: 106651.8 | G25: 19855.388 | H25: 2206.1542 | I25: -29774.844 | J25: -4965.6287 | K25: =SUM(C25:J25) -> -291156.8
A26: Panch_Mahals Total | B26: 2015 | C26: -2958437.7 | D26: -379286.88 | E26: -1879721 | F26: -240989.87 | G26: -44865.136 | H26: -4985.0151 | I26: 67279.089 | J26: 11220.31 | K26: =SUM(C26:J26) -> -5429786.2
A27: Patan Total | B27: 2015 | C27: -16214.249 | D27: -2078.7499 | E27: 2942223.4 | F27: 377208.13 | G27: 70224.918 | H27: 7802.7686 | I27: -105308.24 | J27: -17562.531 | K27: =SUM(C27:J27) -> 3256295.5
A28: Porbandar Total | B28: 2015 | C28: -266051.56 | D28: -34109.174 | E28: -249837.31 | F28: -32030.424 | G28: -5963.1108 | H28: -662.56787 | I28: 8942.1921 | J28: 1491.3128 | K28: =SUM(C28:J28) -> -578220.63
A29: Rajkot Total | B29: 2015 | C29: -195143.98 | D29: -25018.459 | E29: 70907.574 | F29: 9090.7146 | G29: 1692.4203 | H29: 188.0467 | I29: -2537.9282 | J29: -423.25694 | K29: =SUM(C29:J29) -> -141244.87
A30: Sabar_Kantha Total | B30: 2015 | C30: -3072813 | D30: -393950.39 | E30: -2877669 | F30: -368931.93 | G30: -68684.135 | H30: -7631.5706 | I30: 102997.71 | J30: 17177.197 | K30: =SUM(C30:J30) -> -6669505.2
A31: Surat Total | B31: 2015 | C31: -1046613.4 | D31: -134181.21 | E31: 2026199.6 | F31: 259769.18 | G31: 48361.284 | H31: 5373.476 | I31: -72521.86 | J31: -12094.661 | K31: =SUM(C31:J31) -> 1074292.4
A32: Surendranagar Total | B32: 2015 | C32: -855586.39 | D32: -109690.56 | E32: 191027.01 | F32: 24490.642 | G32: 4559.4281 | H32: 506.60312 | I32: -6837.2505 | J32: -1140.2662 | K32: =SUM(C32:J32) -> -752670.78
A33: Tapi Total | B33: 2015 | C33: -1503594.6 | D33: -192768.53 | E33: -648008.16 | F33: -83077.97 | G33: -15466.643 | H33: -1718.5159 | I33: 23193.548 | J33: 3868.0487 | K33: =SUM(C33:J33) -> -2417572.8
A34: Vadodara Total | B34: 2015 | C34: -845669.76 | D34: -108419.2 | E34: 657924.79 | F34: 84349.333 | G34: 15703.333 | H34: 1744.8148 | I34: -23548.484 | J34: -3927.2424 | K34: =SUM(C34:J34) -> -221842.41
... A266: Valsad Total | B266: 2022 | C266: -2460281.4 | D266: -315420.7 | E266: -1733292.3 | F266: -222216.96 | G266: -41370.179 | H266: -4596.6865 | I266: 62038.103 | J266: 10346.257 | K266: =SUM(C266:J266) -> -4704793.9
A268: CO2e GWP20/GWP100(tonnes CO₂e/year) | E268: CO2e GWP20/GWP100(tonnes CO₂e/year) | I268: Top Five Hotspots
A269: District | B269: Year | C269: Emissions(tonnes CO₂e/year) | E269: District | F269: Year | G269: Emissions(tonnes CO₂e/year) | J269: 2015 | K269: 2016 | L269: 2017 | M269: 2018 | N269: 2019 | O269: 2020 | P269: 2021 | Q269: 2022
A270: Ahmadabad Total | B270: 2015 | C270: -126057.35 | E270: Junagadh Total | F270: 2015 | G270: -8286808.7 | I270: Junagadh Total | J270: -8286808.7 | K270: -8295823.4 | L270: -8290718.2 | M270: -8241094.6 | N270: -8118991.8 | O270: -7985981.5 | P270: -7934657.2 | Q270: -7923732.3
A271: Amreli Total | B271: 2015 | C271: -1796071.9 | E271: Sabar_Kantha Total | F271: 2015 | G271: -6669505.2 | I271: Sabar_Kantha Total | J271: -6669505.2 | K271: -6692948.1 | L271: -6578800.8 | M271: -6769369.9 | N271: -6765761.1 | O271: -6502632.9 | P271: -6373260.6 | Q271: -6210811.6
A272: Anand Total | B272: 2015 | C272: 610517.36 | E272: Chhotaudepur Total | F272: 2015 | G272: -5668489 | I272: Chhotaudepur Total | J272: -5668489 | K272: -5990048 | L272: -6141404.5 | M272: -6067724.5 | N272: -5977094.2 | O272: -6021533.7 | P272: -6278751.7 | Q272: -6305409.9
...

Sheet Updated Satellite Data
A1: SUM of area_ha | C1: year
A2: district_name | B2: type_name | C2: 2015 | D2: 2016 | E2: 2017 | F2: 2018 | G2: 2019 | H2: 2020 | I2: 2021 | J2: 2022 | K2: Grand Total
A3: AHMADABAD | B3: Bare areas | C3: 305.4967 | D3: 278.1332 | E3: 292.2392 | F3: 360.1373 | G3: 392.6118 | H3: 335.2511 | I3: 352.1132 | J3: 548.3054 | K3: 2864.2879
B4: Closed deciduous broadleaved forest | C4: 6639.49 | D4: 6208.178 | E4: 5582.637 | F4: 5361.349 | G4: 5262.411 | H4: 3946.45 | I4: 3469.597 | J4: 3763.256 | K4: 40233.368
B5: Closed evergreen broadleaved forest | C5: 2.97 | D5: 4.59 | E5: 3.24 | F5: 3.715059 | G5: 2.97 | H5: 3.42 | I5: 3.42 | J5: 3.24 | K5: 27.565059
B6: Closed evergreen needle-leaved forest | C6: 5.04 | D6: 3.42 | E6: 1.8 | F6: 0.63 | G6: 4.320353 | H6: 2.16 | I6: 9.63 | J6: 9.36 | K6: 36.360353
B7: Consolidated bare areas | C7: 1.44 | D7: 0.54 | E7: 1.08 | F7: 19.26 | G7: 11.34 | H7: 7.74 | I7: 16.02 | J7: 11.7 | K7: 69.12
B8: Deciduous shrubland | C8: 613.9433 | D8: 798.0819 | E8: 594.4747 | F8: 427.5487 | G8: 448.1968 | H8: 490.0027 | I8: 459.9074 | J8: 594.5838 | K8: 4426.7393
B9: Flooded flat | C9: 14558.76 | D9: 16539.46 | E9: 16175.46 | F9: 16874.31 | G9: 16712.32 | H9: 16395.15 | I9: 14263.52 | J9: 12932.12 | K9: 124451.1
B10: Grassland | C10: 25165.57 | D10: 24467.05 | E10: 22232.62 | F10: 23643.4 | G10: 24660.68 | H10: 21860.15 | I10: 22719.44 | J10: 22218.2 | K10: 186967.11
B11: Herbaceous cover cropland | C11: 20403.81 | D11: 20801.5 | E11: 21558.69 | F11: 19871.29 | G11: 19797.62 | H11: 18876.01 | I11: 18583.27 | J11: 18733.43 | K11: 158625.62
B12: Impervious surfaces | C12: 49667.31 | D12: 50375.59 | E12: 51518.96 | F12: 50985.71 | G12: 51546.97 | H12: 51122.79 | I12: 51631.2 | J12: 51615.12 | K12: 408463.65
B13: Irrigated cropland | C13: 191215.6 | D13: 189021.8 | E13: 189554.7 | F13: 186007.3 | G13: 187041.1 | H13: 201756.1 | I13: 208947.1 | J13: 211444.6 | K13: 1564988.3
B14: Mangrove | C14: 2850.197 | D14: 2900.873 | E14: 3217.049 | F14: 3478.256 | G14: 3726.018 | H14: 3773.799 | I14: 3725.986 | J14: 3889.143 | K14: 27561.321
B15: Marsh | C15: 5986.407 | D15: 5767.306 | E15: 4918.903 | F15: 5198.759 | G15: 5667.833 | H15: 5956.523 | I15: 4650.67 | J15: 4812.803 | K15: 42959.204
... B28: Water body | C28: 2677.755 | D28: 2856.879 | E28: 2442.444 | F28: 1901.666 | G28: 2333.513 | H28: 2884.689 | I28: 4799.014 | J28: 4658.829 | K28: 24554.789
A29: AHMADABAD Total | C29: 797859.49 | D29: 797859.4 | E29: 797859.4 | F29: 797859.32 | G29: 797859.38 | H29: 797859.47 | I29: 797859.43 | J29: 797859.4 | K29: 6382875.3
A30: AMRELI | B30: Bare areas | C30: 69.74682 | D30: 52.49259 | E30: 49.95 | F30: 63.29259 | G30: 78.69035 | H30: 43.81729 | I30: 48.42 | J30: 53.64 | K30: 460.04964
B31: Closed deciduous broadleaved forest | C31: 49769.1 | D31: 49858.98 | E31: 46753.21 | F31: 44257.61 | G31: 47317.68 | H31: 51073.19 | I31: 52161.91 | J31: 51118.68 | K31: 392310.36
B32: Closed evergreen broadleaved forest | C32: 5.13 | D32: 8.28 | E32: 7.38 | F32: 6.39 | G32: 6.57 | H32: 9.72 | I32: 7.83 | J32: 7.02 | K32: 58.32
B33: Closed evergreen needle-leaved forest | D33: 1.35 | E33: 0.18 | F33: 0.09 | I33: 0.005294 | J33: 0.455294 | K33: 2.080588
B34: Consolidated bare areas | C34: 0.27 | E34: 0.27 | F34: 1.08 | G34: 0.27 | H34: 0.27 | I34: 0.9 | J34: 0.63 | K34: 3.69
B35: Deciduous shrubland | C35: 427.77 | D35: 450.18 | E35: 404.2888 | F35: 359.6615 | G35: 333.3921 | H35: 334.8233 | I35: 342.5633 | J35: 374.5592 | K35: 3027.2382
B36: Flooded flat | C36: 5824.468 | D36: 5838.266 | E36: 5865.593 | F36: 5551.288 | G36: 5704.26 | H36: 6637.193 | I36: 6672.708 | J36: 6466.387 | K36: 48560.163
B37: Grassland | C37: 3063.12 | D37: 2924.576 | E37: 2829.505 | F37: 3315.52 | G37: 3178.889 | H37: 2855.809 | I37: 2834.77 | J37: 2878.927 | K37: 23881.116
B38: Herbaceous cover cropland | C38: 5535.361 | D38: 5224.169 | E38: 5159.261 | F38: 5071.475 | G38: 5577.968 | H38: 4941.613 | I38: 4825.235 | J38: 4913.402 | K38: 41248.484
B39: Impervious surfaces | C39: 17958.88 | D39: 18361.47 | E39: 19000.55 | F39: 18116.71 | G39: 17471.78 | H39: 18013.52 | I39: 18350 | J39: 18080.29 | K39: 145353.2
B40: Irrigated cropland | C40: 62542.76 | D40: 61909.06 | E40: 59820.12 | F40: 59230.87 | G40: 60632.04 | H40: 60416.2 | I40: 58768.74 | J40: 58720.16 | K40: 482039.95
B41: Mangrove | C41: 1113.422 | D41: 1208.28 | E41: 1225.157 | F41: 1168.264 | G41: 1318.627 | H41: 1311.808 | I41: 1275.207 | J41: 1222.366 | K41: 9843.131
B42: Marsh | C42: 1993.525 | D42: 1835.065 | E42: 1582.708 | F42: 1579.015 | G42: 1922.838 | H42: 2278.158 | I42: 1329.038 | J42: 1346.522 | K42: 13866.869
B43: Open deciduous broadleaved forest | C43: 409.74 | D43: 400.0267 | E43: 356.0209 | F43: 314.1109 | G43: 345.3431 | H43: 334.1294 | I43: 380.8952 | J43: 392.0001 | K43: 2932.2663
B44: Open deciduous needle-leaved forest | C44: 8.28 | D44: 5.58 | E44: 4.05 | F44: 3.69 | G44: 4.14 | H44: 7.2 | I44: 8.28 | J44: 9.72 | K44: 50.94
B45: Open evergreen broadleaved forest | C45: 2748.445 | D45: 2391.557 | E45: 2558.541 | F45: 2991.808 | G45: 3148.897 | H45: 2780.605 | I45: 3023.028 | J45: 3034.574 | K45: 22677.455
B46: Open evergreen needle-leaved forest | C46: 245.2627 | D46: 182.8669 | E46: 161.6573 | F46: 145.2748 | G46: 212.1734 | H46: 248.1614 | I46: 204.6025 | J46: 193.6401 | K46: 1593.6391
... B55: Water body | C55: 3729.916 | D55: 3626.585 | E55: 3516.424 | F55: 3689.28 | G55: 3455.013 | H55: 3004.276 | I55: 4238.967 | J55: 4159.224 | K55: 29419.685
A56: AMRELI Total | C56: 796075.3 | D56: 796075.32 | E56: 796075.39 | F56: 796075.35 | G56: 796075.39 | H56: 796075.33 | I56: 796075.35 | J56: 796075.32 | K56: 6368602.8
A57: ANAND | B57: Bare areas | C57: 86.73741 | D57: 98.39435 | E57: 142.5999 | F57: 189.2418 | G57: 158.7515 | H57: 77.88459 | I57: 60.26224 | J57: 58.49012 | K57: 872.36191
B58: Closed deciduous broadleaved forest | C58: 10168.47 | D58: 10304.86 | E58: 10359.36 | F58: 9834.76 | G58: 8889.212 | H58: 7822.789 | I58: 7511.703 | J58: 7706.804 | K58: 72597.958
B59: Closed evergreen broadleaved forest | C59: 54.25059 | D59: 61.06165 | E59: 58.59882 | F59: 62.31776 | G59: 61.42376 | H59: 58.40612 | I59: 50.54929 | J59: 49.31612 | K59: 455.92411
B60: Closed evergreen needle-leaved forest | C60: 3.42 | D60: 2.97 | E60: 2.43 | F60: 1.62 | G60: 0.9 | H60: 1.71 | I60: 2.189647 | J60: 4.709647 | K60: 19.949294
...

Sheet GLC Forest Land Classes
C2: year | D2: SUM of area_ha
A3: district_name | B3: type_name | C3: 2015 | D3: 2016 | E3: 2017 | F3: 2018 | G3: 2019 | H3: 2020 | I3: 2021 | J3: 2022
A4: Ahmadabad
B5: Closed deciduous broadleaved forest | C5: 6639.49 | D5: 6208.178 | E5: 5582.637 | F5: 5361.349 | G5: 5262.411 | H5: 3946.45 | I5: 3469.597 | J5: 3763.256
B6: Closed evergreen broadleaved forest | C6: 2.97 | D6: 4.59 | E6: 3.24 | F6: 3.715059 | G6: 2.97 | H6: 3.42 | I6: 3.42 | J6: 3.24
B7: Open deciduous broadleaved forest | C7: 181.0616 | D7: 154.3747 | E7: 131.388 | F7: 148.3066 | G7: 249.6166 | H7: 188.1385 | I7: 180.2513 | J7: 192.15
B8: Open evergreen broadleaved forest | C8: 282.546 | D8: 304.8946 | E8: 315.7542 | F8: 195.9349 | G8: 176.9728 | H8: 183.2291 | I8: 240.7031 | J8: 274.0518
B9: Open mixed leaf forest | C9: 590.418 | D9: 570.8047 | E9: 541.8889 | F9: 398.3227 | G9: 511.9055 | H9: 490.6249 | I9: 600.1511 | J9: 609.3939
A10: Ahmadabad Total | C10: =SUM(C5:C9) -> 7696.4856 | D10: =SUM(D5:D9) -> 7242.842 | E10: =SUM(E5:E9) -> 6574.9081 | F10: =SUM(F5:F9) -> 6107.6283 | G10: =SUM(G5:G9) -> 6203.8759 | H10: =SUM(H5:H9) -> 4811.8625 | I10: =SUM(I5:I9) -> 4494.1225 | J10: =SUM(J5:J9) -> 4842.0917
A11: Amreli
B12: Closed deciduous broadleaved forest | C12: 49769.1 | D12: 49858.98 | E12: 46753.21 | F12: 44257.61 | G12: 47317.68 | H12: 51073.19 | I12: 52161.91 | J12: 51118.68
B13: Closed evergreen broadleaved forest | C13: 5.13 | D13: 8.28 | E13: 7.38 | F13: 6.39 | G13: 6.57 | H13: 9.72 | I13: 7.83 | J13: 7.02
B14: Open deciduous broadleaved forest | C14: 409.74 | D14: 400.0267 | E14: 356.0209 | F14: 314.1109 | G14: 345.3431 | H14: 334.1294 | I14: 380.8952 | J14: 392.0001
B15: Open evergreen broadleaved forest | C15: 2748.445 | D15: 2391.557 | E15: 2558.541 | F15: 2991.808 | G15: 3148.897 | H15: 2780.605 | I15: 3023.028 | J15: 3034.574
B16: Open mixed leaf forest | C16: 6092.501 | D16: 6220.438 | E16: 6313.609 | F16: 7124.853 | G16: 6762.5 | H16: 6814.988 | I16: 7692.467 | J16: 7489.173
A17: Amreli Total | C17: =SUM(C12:C16) -> 59024.916 | D17: =SUM(D12:D16) -> 58879.282 | E17: =SUM(E12:E16) -> 55988.761 | F17: =SUM(F12:F16) -> 54694.772 | G17: =SUM(G12:G16) -> 57580.99 | H17: =SUM(H12:H16) -> 61012.632 | I17: =SUM(I12:I16) -> 63266.13 | J17: =SUM(J12:J16) -> 62041.447
A18: Anand
B19: Closed deciduous broadleaved forest | C19: 10168.47 | D19: 10304.86 | E19: 10359.36 | F19: 9834.76 | G19: 8889.212 | H19: 7822.789 | I19: 7511.703 | J19: 7706.804
B20: Closed evergreen broadleaved forest | C20: 54.25059 | D20: 61.06165 | E20: 58.59882 | F20: 62.31776 | G20: 61.42376 | H20: 58.40612 | I20: 50.54929 | J20: 49.31612
B21: Open deciduous broadleaved forest | C21: 99.12 | D21: 99.04941 | E21: 96.13835 | F21: 94.58259 | G21: 113.0086 | H21: 102.2153 | I21: 94.06482 | J21: 93.70376
B22: Open evergreen broadleaved forest | C22: 180.4108 | D22: 177.2072 | E22: 161.5666 | F22: 145.0856 | G22: 178.086 | H22: 209.6806 | I22: 269.8638 | J22: 259.5138
B23: Open mixed leaf forest | C23: 45.05859 | D23: 45 | E23: 33.36812 | F23: 41.72224 | G23: 77.20059 | H23: 62.58388 | I23: 61.86388 | J23: 56.64388
A24: Anand Total | C24: =SUM(C19:C23) -> 10547.31 | D24: =SUM(D19:D23) -> 10687.178 | E24: =SUM(E19:E23) -> 10709.032 | F24: =SUM(F19:F23) -> 10178.468 | G24: =SUM(G19:G23) -> 9318.9309 | H24: =SUM(H19:H23) -> 8255.6749 | I24: =SUM(I19:I23) -> 7988.0448 | J24: =SUM(J19:J23) -> 8165.9816
A25: Arvalli
B26: Closed deciduous broadleaved forest | C26: 155152.7 | D26: 158938.6 | E26: 156162.1 | F26: 156821.8 | G26: 151592.1 | H26: 134537.9 | I26: 127980.2 | J26: 125856.1
B27: Closed evergreen broadleaved forest | C27: 29.79494 | D27: 26.28494 | E27: 25.83494 | F27: 25.74494 | G27: 24.918 | H27: 21.24494 | I27: 21.60494 | J27: 21.33494
B28: Open deciduous broadleaved forest | C28: 173.5384 | D28: 183.9092 | E28: 150.6992 | F28: 178.1746 | G28: 191.2853 | H28: 260.4992 | I28: 442.1079 | J28: 367.9401
B29: Open evergreen broadleaved forest | C29: 1980.453 | D29: 1781.023 | E29: 1822.666 | F29: 1826.454 | G29: 2049.038 | H29: 2328.959 | I29: 2503.043 | J29: 2481.304
B30: Open mixed leaf forest | C30: 2604.143 | D30: 2027.275 | E30: 2460.83 | F30: 2738.948 | G30: 2976.742 | H30: 3141.944 | I30: 2915.871 | J30: 2914.819
A31: Arvalli Total | C31: =SUM(C26:C30) -> 159940.63 | D31: =SUM(D26:D30) -> 162957.09 | E31: =SUM(E26:E30) -> 160622.13 | F31: =SUM(F26:F30) -> 161591.12 | G31: =SUM(G26:G30) -> 156834.08 | H31: =SUM(H26:H30) -> 140290.55 | I31: =SUM(I26:I30) -> 133862.83 | J31: =SUM(J26:J30) -> 131641.5
A32: Banas_Kantha
B33: Closed deciduous broadleaved forest | C33: 93821.69 | D33: 93905.81 | E33: 94474.58 | F33: 97353.68 | G33: 98458.82 | H33: 96514.58 | I33: 94794.24 | J33: 94355.64
B34: Closed evergreen broadleaved forest | C34: 13.90376 | D34: 14.26376 | E34: 13.27376 | F34: 10.93376 | G34: 11.20376 | H34: 10.21376 | I34: 8.773765 | J34: 8.593765
B35: Open deciduous broadleaved forest | C35: 340.4675 | D35: 384.7588 | E35: 350.4681 | F35: 340.0327 | G35: 325.9998 | H35: 307.0334 | I35: 326.1784 | J35: 320.0259
B36: Open evergreen broadleaved forest | C36: 2314.028 | D36: 2117.82 | E36: 1994.38 | F36: 1795.359 | G36: 1899.413 | H36: 1896.282 | I36: 2254.659 | J36: 2231.052
B37: Open mixed leaf forest | C37: 2061.841 | D37: 1926.708 | E37: 1908.521 | F37: 1879.733 | G37: 2046.351 | H37: 2226.356 | I37: 2332.457 | J37: 2313.616
A38: Banas_Kantha Total | C38: =SUM(C33:C37) -> 98551.93 | D38: =SUM(D33:D37) -> 98349.361 | E38: =SUM(E33:E37) -> 98741.223 | F38: =SUM(F33:F37) -> 101379.74 | G38: =SUM(G33:G37) -> 102741.79 | H38: =SUM(H33:H37) -> 100954.47 | I38: =SUM(I33:I37) -> 99716.308 | J38: =SUM(J33:J37) -> 99228.928
A39: Bharuch
B40: Closed deciduous broadleaved forest | C40: 18728.25 | D40: 19940.19 | E40: 20695.32 | F40: 19561.94 | G40: 18904.38 | H40: 18464.6 | I40: 19815.74 | J40: 20662.88
B41: Closed evergreen broadleaved forest | C41: 6.66 | D41: 7.02 | E41: 9.27 | F41: 11.07 | G41: 10.44 | H41: 14.49 | I41: 12.69 | J41: 12.24
...

Sheet Forest Land SUM of area_ha
B2: year | C2: SUM of area_ha
A3: district_name | B3: 2015 | C3: 2016 | D3: 2017 | E3: 2018 | F3: 2019 | G3: 2020 | H3: 2021 | I3: 2022
A4: Ahmadabad Total | B4: 7696.4856 | C4: 7242.842 | D4: 6574.9081 | E4: 6107.6283 | F4: 6203.8759 | G4: 4811.8625 | H4: 4494.1225 | I4: 4842.0917
A5: Amreli Total | B5: 59024.916 | C5: 58879.282 | D5: 55988.761 | E5: 54694.772 | F5: 57580.99 | G5: 61012.632 | H5: 63266.13 | I5: 62041.447
A6: Anand Total | B6: 10547.31 | C6: 10687.178 | D6: 10709.032 | E6: 10178.468 | F6: 9318.9309 | G6: 8255.6749 | H6: 7988.0448 | I6: 8165.9816
A7: Arvalli Total | B7: 159940.63 | C7: 162957.09 | D7: 160622.13 | E7: 161591.12 | F7: 156834.08 | G7: 140290.55 | H7: 133862.83 | I7: 131641.5
A8: Banas_Kantha Total | B8: 98551.93 | C8: 98349.361 | D8: 98741.223 | E8: 101379.74 | F8: 102741.79 | G8: 100954.47 | H8: 99716.308 | I8: 99228.928
A9: Bharuch Total | B9: 20779.118 | C9: 21833.535 | D9: 22630.645 | E9: 21590.444 | F9: 20989.659 | G9: 20754.649 | H9: 22549.617 | I9: 23342.411
A10: Bhavnagar Total | B10: 30892.888 | C10: 31502.922 | D10: 30311.911 | E10: 29034.206 | F10: 30140.604 | G10: 31399.841 | H10: 32370.427 | I10: 31800.374
A11: Botad Total | B11: 3702.4791 | C11: 3692.5963 | D11: 3791.8189 | E11: 4039.4247 | F11: 4358.7816 | G11: 3433.7303 | H11: 3136.1296 | I11: 3137.2835
A12: Chhotaudepur Total | B12: 176061.47 | C12: 185939.78 | D12: 190641.05 | E12: 188499.43 | F12: 185872.47 | G12: 186778.96 | H12: 194536.84 | I12: 195356.76
A13: Dahod Total | B13: 153720.13 | C13: 162562.08 | D13: 164826.42 | E13: 161028.36 | F13: 157021.12 | G13: 150827.27 | H13: 151506.4 | I13: 150519.25
